Workbook

Sheet Orders
A1: order_id | B1: order_date | C1: customer_id | D1: product_id | E1: sales_rep_id | F1: quantity | G1: unit_price | H1: discount_pct | I1: final_amount | J1: payment_status | K1: ship_city
A2: ORD-00001 | B2: 45549 | C2: CUST-0243 | D2: PROD-014 | E2: R007 | F2: 8 | G2: 3620 | H2: 15.4 | I2: 24500.16 | J2: Completed | K2: Pune
A3: ORD-00002 | B3: 45340 | C3: CUST-0202 | D3: PROD-020 | E3: R005 | F3: 2 | G3: 820 | H3: 10.8 | I3: 1462.88 | J3: Pending | K3: Chennai
A4: ORD-00003 | B4: 45371 | C4: CUST-0098 | D4: PROD-053 | E4: R014 | F4: 8 | G4: 470 | H4: 3.3 | I4: 3635.92 | J4: Pending | K4: Delhi
A5: ORD-00004 | B5: 45413 | C5: CUST-0071 | D5: PROD-028 | E5: R006 | F5: 1 | G5: 3660 | H5: 15.7 | I5: 3085.38 | J5: Completed | K5: Delhi
A6: ORD-00005 | B6: 45611 | C6: CUST-0180 | D6: PROD-012 | E6: R008 | F6: 1 | G6: 3160 | H6: 26 | I6: 2338.4 | J6: Completed | K6: Chennai
A7: ORD-00006 | B7: 45406 | C7: CUST-0275 | D7: PROD-032 | E7: R025 | F7: 4 | G7: 370 | H7: 29 | I7: 1050.8 | J7: Completed | K7: Mumbai
A8: ORD-00007 | B8: 45455 | C8: CUST-0293 | D8: PROD-057 | E8: R024 | F8: 3 | G8: 960 | H8: 5.8 | I8: 2712.96 | J8: Completed | K8: Bengaluru
A9: ORD-00008 | B9: 45617 | C9: CUST-0281 | D9: PROD-007 | E9: R019 | F9: 8 | G9: 1430 | H9: 2.4 | I9: 11165.44 | J9: Completed | K9: Bengaluru
A10: ORD-00009 | B10: 45549 | C10: CUST-0260 | D10: PROD-038 | E10: R008 | F10: 3 | G10: 5490 | H10: 14.2 | I10: 14131.26 | J10: Completed | K10: Bengaluru
A11: ORD-00010 | B11: 45396 | C11: CUST-0147 | D11: PROD-030 | E11: R028 | F11: 3 | G11: 970 | H11: 1.2 | I11: 2875.08 | J11: Completed | K11: Pune
A12: ORD-00011 | B12: 45560 | C12: CUST-0204 | D12: PROD-024 | E12: R010 | F12: 7 | G12: 2270 | H12: 7.1 | I12: 14761.81 | J12: Pending | K12: Hyderabad
A13: ORD-00012 | B13: 45332 | C13: CUST-0147 | D13: PROD-010 | E13: R024 | F13: 9 | G13: 2640 | H13: 21.7 | I13: 18604.08 | J13: Completed | K13: Pune
... A2001: ORD-02000 | B2001: 45325 | C2001: CUST-0238 | D2001: PROD-034 | E2001: R023 | F2001: 6 | G2001: 5080 | H2001: 28.1 | I2001: 21915.12 | J2001: Completed | K2001: Delhi

Sheet Customers
A1: customer_id | B1: customer_name | C1: age | D1: city | E1: segment | F1: signup_date
A2: CUST-0001 | B2: Amit Agarwal | C2: 36 | D2: Pune | E2: Retail | F2: 44819
A3: CUST-0002 | B3: Vihaan Malhotra | C3: 42 | D3: Pune | E3: Corporate | F3: 44984
A4: CUST-0003 | B4: Navya Malhotra | C4: 33 | D4: Mumbai | E4: Retail | F4: 44059
A5: CUST-0004 | B5: Aaradhya Mehta | C5: 53 | D5: delhi | E5: Retail | F5: 44054
A6: CUST-0005 | B6: Myra Malhotra | C6: 52 | D6: Chennai | E6: Corporate | F6: 45037
A7: CUST-0006 | B7: Shaurya Iyer | C7: 44 | D7: Pune | E7: SMB | F7: 44302
A8: CUST-0007 | B8: Dhruv Joshi | C8: 47 | D8: Bengaluru | E8: Retail | F8: 44498
A9: CUST-0008 | B9: Kavita Malhotra | C9: 39 | D9: Pune | E9: SMB | F9: 45162
A10: CUST-0009 | B10: Neha Malhotra | C10: 61 | D10: Mumbai | E10: Retail | F10: 44343
A11: CUST-0010 | B11: Aaradhya Gupta | C11: 61 | D11: Mumbai | E11: SMB | F11: 44975
A12: CUST-0011 | B12: Diya Menon | C12: 41 | D12: Chennai | E12: Corporate | F12: 44821
A13: CUST-0012 | B13: Prisha Desai | C13: 43 | D13: Pune | E13: Retail | F13: 44718
... A301: CUST-0300 | B301: Rohit Nair | C301: 38 | D301: Mumbai | E301: Retail | F301: 43932

Sheet Products
A1: product_id | B1: product_name | C1: category | D1: unit_cost | E1: unit_price | F1: is_active
A2: PROD-001 | B2: Smartphone Pro | C2: Electronics | D2: 2405 | E2: 5330 | F2: TRUE
A3: PROD-002 | B3: Wireless Earbuds | C3: Electronics | D3: 1052 | E3: 2600 | F3: TRUE
A4: PROD-003 | B4: Smart Watch | C4: Electronics | D4: 1665 | E4: 3570 | F4: TRUE
A5: PROD-004 | B5: Laptop Bag | C5: Electronics | D5: 1559 | E5: 3870 | F5: TRUE
A6: PROD-005 | B6: Power Bank | C6: Electronics | D6: 128 | E6: 300 | F6: TRUE
A7: PROD-006 | B7: Bluetooth Speaker | C7: Electronics | D7: 2865 | E7: 3970 | F7: TRUE
A8: PROD-007 | B8: USB-C Cable | C8: Electronics | D8: 861 | E8: 1430 | F8: TRUE
A9: PROD-008 | B9: Wireless Mouse | C9: Electronics | D9: 1259 | E9: 2660 | F9: FALSE
A10: PROD-009 | B10: Mechanical Keyboard | C10: Electronics | D10: 517 | E10: 1220 | F10: TRUE
A11: PROD-010 | B11: Tablet Stand | C11: Electronics | D11: 1149 | E11: 2640 | F11: TRUE
A12: PROD-011 | B12: Cotton T-Shirt | C12: Apparel | D12: 1748 | E12: 3450 | F12: TRUE
A13: PROD-012 | B13: Denim Jeans | C13: Apparel | D13: 1886 | E13: 3160 | F13: TRUE
... A61: PROD-060 | B61: Gym Gloves | C61: Sports | D61: 147 | E61: 190 | F61: TRUE

Sheet Sales_Reps
A1: rep_id | B1: rep_name | C1: region | D1: hire_date | E1: team_lead_id
A2: R001 | B2: Rajesh Malhotra | C2: North | D2: 44207
A3: R002 | B3: Sunita Malhotra | C3: North | D3: 44028
A4: R003 | B4: Amit Singh | C4: North | D4: 43651
A5: R004 | B5: Priya Singh | C5: North | D5: 44907
A6: R005 | B6: Vikram Patel | C6: North | D6: 43588 | E6: R001
A7: R006 | B7: Neha Desai | C7: North | D7: 44131 | E7: R001
A8: R007 | B8: Suresh Menon | C8: North | D8: 43493 | E8: R001
A9: R008 | B9: Kavita Patel | C9: North | D9: 44693 | E9: R001
A10: R009 | B10: Manoj Patel | C10: South | D10: 44804 | E10: R002
A11: R010 | B11: Divya Rao | C11: South | D11: 43904 | E11: R002
A12: R011 | B12: Anil Verma | C12: South | D12: 44622 | E12: R002
A13: R012 | B13: Pooja Nair | C13: South | D13: 44890 | E13: R002
A14: R013 | B14: Sanjay Kapoor | C14: South | D14: 45215 | E14: R002
A15: R014 | B15: Ritu Menon | C15: South | D15: 44469 | E15: R002
A16: R015 | B16: Deepak Shah | C16: South | D16: 45231 | E16: R002
A17: R016 | B17: Anjali Chopra | C17: South | D17: 43614 | E17: R002
... A31: R030 | B31: Kiran Bhatt | C31: West | D31: 44506 | E31: R004

Sheet Targets
A1: rep_id | B1: Jan-24 | C1: Feb-24 | D1: Mar-24 | E1: Apr-24 | F1: May-24 | G1: Jun-24 | H1: Jul-24 | I1: Aug-24 | J1: Sep-24 | K1: Oct-24 | L1: Nov-24 | M1: Dec-24
A2: R001 | B2: 231324 | C2: 171682 | D2: 234376 | E2: 326967 | F2: 350588 | G2: 385324 | H2: 307980 | I2: 327947 | J2: 181016 | K2: 374039 | L2: 212805 | M2: 405999
A3: R002 | B3: 438126 | C3: 346266 | D3: 329993 | E3: 370744 | F3: 294660 | G3: 341556 | H3: 151934 | I3: 223794 | J3: 438641 | K3: 344308 | L3: 296172 | M3: 304288
A4: R003 | B4: 358703 | C4: 320519 | D4: 327321 | E4: 298753 | F4: 254636 | G4: 351929 | H4: 264723 | I4: 216459 | J4: 391945 | K4: 362426 | L4: 289199 | M4: 301863
A5: R004 | B5: 389594 | C5: 376422 | D5: 324156 | E5: 420255 | F5: 409107 | G5: 269954 | H5: 179097 | I5: 370568 | J5: 387395 | K5: 243454 | L5: 232530 | M5: 201999
A6: R005 | B6: 436862 | C6: 391158 | D6: 340224 | E6: 170548 | F6: 229390 | G6: 349525 | H6: 154683 | I6: 320848 | J6: 354452 | K6: 377180 | L6: 342347 | M6: 183362
A7: R006 | B7: 348734 | C7: 358191 | D7: 250385 | E7: 219657 | F7: 249365 | G7: 435704 | H7: 260892 | I7: 250741 | J7: 358402 | K7: 379858 | L7: 213280 | M7: 224634
A8: R007 | B8: 280057 | C8: 330342 | D8: 336856 | E8: 227425 | F8: 233647 | G8: 307088 | H8: 370724 | I8: 440008 | J8: 406347 | K8: 217357 | L8: 299289 | M8: 214568
A9: R008 | B9: 252886 | C9: 206057 | D9: 318209 | E9: 411230 | F9: 448660 | G9: 171135 | H9: 305339 | I9: 432264 | J9: 294273 | K9: 371409 | L9: 284207 | M9: 437068
A10: R009 | B10: 268752 | C10: 393256 | D10: 310649 | E10: 246237 | F10: 271287 | G10: 314545 | H10: 406506 | I10: 334930 | J10: 348625 | K10: 408928 | L10: 243749 | M10: 418409
A11: R010 | B11: 384734 | C11: 156698 | D11: 283679 | E11: 276085 | F11: 409270 | G11: 285230 | H11: 304233 | I11: 178221 | J11: 284216 | K11: 287373 | L11: 229082 | M11: 298969
A12: R011 | B12: 186029 | C12: 151419 | D12: 253251 | E12: 379757 | F12: 204209 | G12: 179396 | H12: 378008 | I12: 182649 | J12: 267772 | K12: 350352 | L12: 358042 | M12: 359960
A13: R012 | B13: 352158 | C13: 251181 | D13: 321255 | E13: 300863 | F13: 241731 | G13: 393275 | H13: 313561 | I13: 283604 | J13: 429065 | K13: 194420 | L13: 254168 | M13: 389283
... A31: R030 | B31: 151584 | C31: 221679 | D31: 385157 | E31: 290386 | F31: 236041 | G31: 407985 | H31: 184446 | I31: 342894 | J31: 180344 | K31: 292917 | L31: 314858 | M31: 364057

Sheet Q1_Lookups
A1: Q1 - LOOKUP FUNCTIONS (25 marks total)
A2: VLOOKUP · INDEX-MATCH · Two-way lookup · Chain lookup · Approximate lookup · Self-join
A4: Q# | B4: Question | C4: Marks | D4: Hint | E4: Your Answer | F4: Format
A5: Q1.1 | B5: For order ORD-00234, what is the customer_id? | C5: 3 | D5: Simple VLOOKUP on Orders sheet. | E5: =Calculations!$U$2 -> CUST-0173 | F5: CUST-####
A6: Q1.2 | B6: For order ORD-00456, what is the product_name? (You will need to look up the product_id first, then find its name in Products.) | C6: 3 | D6: Two-step lookup, or nested VLOOKUP. | E6: =Calculations!$U$3 -> Dumbbells 5kg | F6: Text
A7: Q1.3 | B7: For order ORD-00987, what is the rep_name of the sales rep? Note: the rep_name is in a column that appears to the LEFT of what you might look up first. | C7: 3 | D7: VLOOKUP has directional limits - INDEX/MATCH does not. | E7: =Calculations!$U$4 -> Nisha Menon | F7: Text
A8: Q1.4 | B8: From the Targets sheet, what is the target value for rep R012 in the month Mar-24? | C8: 4 | D8: Two-way lookup: row = rep_id, column = month. | E8: =Calculations!$U$5 -> 321255 | F8: Whole number
A9: Q1.5 | B9: For order ORD-01500, what is the CATEGORY of the product ordered? (Chain: order → product_id → category) | C9: 4 | D9: Multi-hop lookup across sheets. | E9: =Calculations!$U$6 -> Electronics | F9: Text
A10: Q1.6 | B10: For order ORD-00789, which DISCOUNT SLAB does it fall in? Use the slab table below (rows 20-24). Slab breakpoints are the LOWER bound of each range. | C10: 3 | D10: Approximate-match VLOOKUP (sort ascending, TRUE / omit last arg). | E10: =Calculations!$U$7 -> Bronze | F10: Text
A11: Q1.7 | B11: For order ORD-01234, in one cell produce the string: "<rep_name> (<sales_region>)" - e.g. "Amit Singh (South)". | C11: 3 | D11: Two lookups joined with & or CONCATENATE. | E11: =Calculations!$U$8 -> Sanjay Kapoor (South) | F11: Text
A12: Q1.8 | B12: What is the rep_name of the TEAM LEAD for rep R017? (The Sales_Reps sheet has team_lead_id - you need to self-join to find that person's name.) | C12: 2 | D12: Look up the team_lead_id, then look up THAT id's rep_name. | E12: =Calculations!$U$9 -> Amit Singh | F12: Text
B15: DISCOUNT SLAB REFERENCE TABLE (use for Q1.6)
B17: Discount % (Lower) | C17: Slab
B18: 0 | C18: Bronze
B19: 5 | C19: Silver
B20: 15 | C20: Gold
B21: 25 | C21: Platinum

Sheet Q2_Cleaning
A1: Q2 - DATA CLEANING & QUALITY DIAGNOSTICS (20 marks total)
A2: Duplicates · Whitespace · Case Inconsistency · Referential Integrity · Discontinued SKUs · Anomaly Patterns
A4: Q# | B4: Question | C4: Marks | D4: Hint | E4: Your Answer | F4: Format
A5: Q2.1 | B5: How many DUPLICATE rows exist in the Orders sheet (i.e., how many order_id values appear more than once)? Count each duplicate as ONE (not the extras). | C5: 3 | D5: COUNTIF > 1, then count. Watch what you're counting - rows or IDs. | E5: =Calculations!$U$10 -> 20 | F5: Whole number
A6: Q2.2 | B6: How many customers in the Customers sheet have LEADING or TRAILING whitespace in their customer_name? | C6: 3 | D6: Compare LEN vs LEN(TRIM). Or use SUMPRODUCT with a boolean. | E6: =Calculations!$U$11 -> 15 | F6: Whole number
A7: Q2.3 | B7: The Customers sheet has some cities in inconsistent case (e.g., "mumbai", "MUMBAI", "Mumbai"). How many DISTINCT cities exist AFTER standardizing case? | C7: 3 | D7: Combine PROPER/UPPER with a de-dup count. SUMPRODUCT + 1/COUNTIF trick works. | E7: =Calculations!$U$12 -> 6 | F7: Whole number
A8: Q2.4 | B8: How many orders reference a customer_id that DOES NOT EXIST in the Customers sheet? (Broken foreign key) | C8: 4 | D8: Use MATCH with ISNA/ISERROR, then count. | E8: =Calculations!$U$13 -> 30 | F8: Whole number
A9: Q2.5 | B9: How many orders reference a product that is currently DISCONTINUED (is_active = FALSE in the Products sheet)? | C9: 3 | D9: VLOOKUP the is_active flag, then count where FALSE. | E9: =Calculations!$U$14 -> 174 | F9: Whole number
A10: Q2.6 | B10: Find the "suspicious pattern": how many orders have payment_status = "Cancelled" AND a discount_pct > 20%? (This pattern often indicates promo abuse - a real-world diagnostic query.) | C10: 4 | D10: COUNTIFS with two criteria. | E10: =Calculations!$U$15 -> 58 | F10: Whole number

Sheet Q3_Aggregation
A1: Q3 - CONDITIONAL AGGREGATION (25 marks total)
A2: SUMIFS · COUNTIFS · AVERAGEIFS · Nested IF logic · Multi-sheet aggregation · Top-N logic
A4: Q# | B4: Question | C4: Marks | D4: Hint | E4: Your Answer | F4: Format
A5: Q3.1 | B5: What is the TOTAL REVENUE (sum of final_amount) for orders in Q3 2024 (Jul-Sep) where ship_city is Mumbai? | C5: 4 | D5: SUMIFS with 3 conditions: date >= start, date <= end, city = Mumbai. Beware case issues. | E5: =Calculations!$U$16 -> 1217239 | F5: Currency
A6: Q3.2 | B6: How many orders have discount_pct > 15% AND payment_status = "Completed"? | C6: 3 | D6: COUNTIFS with two conditions. | E6: =Calculations!$U$17 -> 723 | F6: Whole number
A7: Q3.3 | B7: What is the AVERAGE final_amount for orders where the product CATEGORY is "Electronics" AND the customer SEGMENT is "Corporate"? Note: Both fields come from OTHER sheets - you'll need helper columns. | C7: 5 | D7: Helper columns in Orders: VLOOKUP category from Products, VLOOKUP segment from Customers. Then AVERAGEIFS. | E7: =Calculations!$U$18 -> 13981.402 | F7: Currency
A8: Q3.4 | B8: What is the COMBINED REVENUE of the TOP 3 reps by total revenue? (Sum of the 3 highest rep totals.) | C8: 4 | D8: Compute per-rep totals, then use SUMPRODUCT with LARGE, or sort and sum top 3. | E8: =Calculations!$U$19 -> 3342678.5 | F8: Currency
A9: Q3.5 | B9: For rep R015 in Nov-24: compute the actual revenue and compare to the target (from Targets sheet). Report the PERFORMANCE TIER using: <80% → "Below", 80-120% → "On Track", >120% → "Exceeds". Return only the tier text. | C9: 5 | D9: Nested IF (or IFS): compute actual/target ratio, then classify. | E9: =Calculations!$U$20 -> Below | F9: Text
A10: Q3.6 | B10: What is the TOTAL revenue from Corporate segment customers aged between 30 and 40 (both inclusive)? | C10: 4 | D10: Helper columns for age and segment. Then SUMIFS with numeric range. | E10: =Calculations!$U$21 -> 982568.4 | F10: Currency

Sheet Q4_Pivot
A1: Q4 - PIVOT TABLES (20 marks total)
A2: 2D Pivots · Filters · % of Row Total · Date Grouping · Calculated Fields · Cross-Sheet Data
A4: Q# | B4: Question | C4: Marks | D4: Hint | E4: Your Answer | F4: Format
A5: Q4.1 | B5: Build a pivot with sales_region as rows and product category as columns, values = SUM of final_amount. What value appears at the intersection of "South" and "Electronics"? | C5: 4 | D5: You need to add category (from Products) and region (from Sales_Reps) as columns to Orders first. Insert PivotTable from combined data. | E5: =Calculations!$U$22 -> 1314107.4 | F5: Currency
A6: Q4.2 | B6: Build a pivot: rows = order month (Jan-24 through Dec-24), columns = sales_rep_id, values = SUM of final_amount. What is the HIGHEST single value in the entire pivot? (One number.) | C6: 4 | D6: After building, use MAX() over the pivot data range, or scan visually. | E6: =Calculations!$U$23 -> 216421.52 | F6: Currency
A7: Q4.3 | B7: For the North sales_region only: what PERCENTAGE of total revenue comes from the Apparel category? Configure the pivot with Show Values As → % of Row Total. | C7: 4 | D7: Pivot: rows=region, cols=category, values=sum(final_amount), Show Values As = % of Row Total. | E7: =Calculations!$U$24 -> 0.1402315 | F7: Percentage
A8: Q4.4 | B8: Group order dates by QUARTER in a pivot. What is the total revenue for Q4 2024 (Oct-Dec)? | C8: 4 | D8: PivotTable → Group By → Quarter. Or SUMIFS with date range. | E8: =Calculations!$U$25 -> 6459443 | F8: Currency
A9: Q4.5 | B9: Create a CALCULATED FIELD in the pivot: profit_margin = (unit_price - unit_cost) / unit_price. What is the AVERAGE profit_margin for orders shipped to Delhi? Give as a percentage. | C9: 4 | D9: Add unit_cost via VLOOKUP as helper column. Create pivot calculated field, filter to Delhi. | E9: =Calculations!$U$26 -> 0.44880873 | F9: Percentage

Sheet Q5_Advanced
A1: Q5 - ADVANCED (10 marks total)
A2: RANK · Running Totals · TEXTJOIN · LARGE + INDEX/MATCH · Multi-condition top-N
A4: Q# | B4: Question | C4: Marks | D4: Hint | E4: Your Answer | F4: Format
A5: Q5.1 | B5: Rank all sales reps by total revenue (highest = rank 1). Who (name) is at RANK #7? | C5: 2 | D5: Per-rep totals, then use RANK.EQ, or sort. Return the rep_name at position 7. | E5: =Calculations!$U$27 -> #N/A | F5: Text
A6: Q5.2 | B6: What is the CUMULATIVE revenue from Jan 2024 through the end of Aug 2024? (Sum of final_amount where order_date <= 31-Aug-2024.) | C6: 2 | D6: SUMIFS with date <=. | E6: =Calculations!$U$28 -> 18050690 | F6: Currency
A7: Q5.3 | B7: Among orders where the sales rep is in the WEST region: which product (by name) has the 2nd highest total revenue? | C7: 3 | D7: Helper: sales_region on orders. Filter/pivot to West, sum by product, rank, get #2, VLOOKUP product name. | E7: =Calculations!$U$29 -> #N/A | F7: Text
A8: Q5.4 | B8: Concatenate the names of the top 5 reps by revenue into a single cell, separated by " | " (space-pipe-space). | C8: 2 | D8: TEXTJOIN with delimiter " | ". Combine with LARGE to pull top 5. | E8: =Calculations!$U$30 -> #NAME? | F8: Text
A9: Q5.5 | B9: What is the HIGHEST single order value (final_amount) where ship_city = "Bengaluru" AND the product's category = "Grocery"? | C9: 1 | D9: MAXIFS with a category helper column, or nested MAX(IF()). | E9: =Calculations!$U$31 -> #NAME? | F9: Currency

Sheet Calculations
A1: Order ID | B1: Order Date | C1: Customer ID | D1: Product ID | E1: Sales Rep ID | F1: Quantity | G1: Unit Price | H1: Discount % | I1: Final Amount | J1: Payment Status | K1: Ship City | L1: Category | M1: Unit Cost | N1: Sales Region | O1: Customer Segment | P1: Customer Age | Q1: Profit Margin | R1: Customer Check | S1: Active Product? | T1: Question | U1: Answer / Calculation | V1: Beginner formula used | W1: Rep ID | X1: Rep Name | Y1: Total Revenue | Z1: Rank | AB1: Month | AC1: R001 | AD1: R002 | AE1: R003 | AF1: R004 | AG1: R005 | AH1: R006 | AI1: R007 | AJ1: R008 | AK1: R009 | AL1: R010 | AM1: R011 | AN1: R012 | AO1: R013 | AP1: R014 | AQ1: R015 | AR1: R016 | AS1: R017 | AT1: R018 | AU1: R019 | AV1: R020 | AW1: R021 | AX1: R022 | AY1: R023 | AZ1: R024 | BA1: R025 | BB1: R026 | BC1: R027 | BD1: R028 | BE1: R029 | BF1: R030 | BH1: Product ID | BI1: Product Name | BJ1: West Revenue | BK1: West Rank | BL1: Duplicate Share | BM1: Name Has Extra Space | BN1: City Unique Share | BO1: Missing Customer | BP1: Inactive Product
A2: =Orders!A2 -> ORD-00001 | B2: =Orders!B2 -> 45549 | C2: =Orders!C2 -> CUST-0243 | D2: =Orders!D2 -> PROD-014 | E2: =Orders!E2 -> R007 | F2: =Orders!F2 -> 8 | G2: =Orders!G2 -> 3620 | H2: =Orders!H2 -> 15.4 | ... K2: =Orders!K2 -> Pune | L2: =IFERROR(VLOOKUP(D2,Products!$A$2:$F$61,3,FALSE),"") -> Apparel | M2: =IFERROR(VLOOKUP(D2,Products!$A$2:$F$61,4,FALSE),"") -> 2509 | N2: =IFERROR(VLOOKUP(E2,Sales_Reps!$A$2:$E$31,3,FALSE),"") -> North | O2: =IFERROR(VLOOKUP(C2,Customers!$A$2:$F$301,5,FALSE),"") -> SMB | P2: =IFERROR(VLOOKUP(C2,Customers!$A$2:$F$301,3,FALSE),"") -> 44 | Q2: =IFERROR((G2-M2)/G2,0) -> 0.30690608 | R2: =IFERROR(VLOOKUP(C2,Customers!$A$2:$F$301,1,FALSE),"") -> CUST-0243 | S2: =IFERROR(VLOOKUP(D2,Products!$A$2:$F$61,6,FALSE),"") -> TRUE | T2: Q1.1 | U2: =INDEX($C$2:$C$2001,MATCH("ORD-00234",$A$2:$A$2001,0)) -> CUST-0173 | V2: INDEX + MATCH | W2: =Sales_Reps!A2 -> R001 | X2: =Sales_Reps!B2 -> Rajesh Malhotra | Y2: =SUMIF($E$2:$E$2001,W2,$I$2:$I$2001) -> 789849.6 | Z2: =_xludf.RANK.EQ(Y2,$Y$2:$Y$31,0) -> #NAME? | AB2: =DATE(2024,1,1) -> 45292 | AC2: =SUMIFS($I$2:$I$2001,$B$2:$B$2001,">="&$AB2,$B$2:$B$2001,"<"&EDATE($AB2,1),$E$2:$E$2001,AC$1) -> 43650.56 | AD2: =SUMIFS($I$2:$I$2001,$B$2:$B$2001,">="&$AB2,$B$2:$B$2001,"<"&EDATE($AB2,1),$E$2:$E$2001,AD$1) -> 51707.32 | AE2: =SUMIFS($I$2:$I$2001,$B$2:$B$2001,">="&$AB2,$B$2:$B$2001,"<"&EDATE($AB2,1),$E$2:$E$2001,AE$1) -> 54307 | AF2: =SUMIFS($I$2:$I$2001,$B$2:$B$2001,">="&$AB2,$B$2:$B$2001,"<"&EDATE($AB2,1),$E$2:$E$2001,AF$1) -> 57892.11 | AG2: =SUMIFS($I$2:$I$2001,$B$2:$B$2001,">="&$AB2,$B$2:$B$2001,"<"&EDATE($AB2,1),$E$2:$E$2001,AG$1) -> 70665.51 | AH2: =SUMIFS($I$2:$I$2001,$B$2:$B$2001,">="&$AB2,$B$2:$B$2001,"<"&EDATE($AB2,1),$E$2:$E$2001,AH$1) -> 84968.56 | AI2: =SUMIFS($I$2:$I$2001,$B$2:$B$2001,">="&$AB2,$B$2:$B$2001,"<"&EDATE($AB2,1),$E$2:$E$2001,AI$1) -> 92029.91 | AJ2: =SUMIFS($I$2:$I$2001,$B$2:$B$2001,">="&$AB2,$B$2:$B$2001,"<"&EDATE($AB2,1),$E$2:$E$2001,AJ$1) -> 61557.02 | ... BF2: =SUMIFS($I$2:$I$2001,$B$2:$B$2001,">="&$AB2,$B$2:$B$2001,"<"&EDATE($AB2,1),$E$2:$E$2001,BF$1) -> 59170.81 | BH2: =Products!A2 -> PROD-001 | BI2: =Products!B2 -> Smartphone Pro | BJ2: =SUMIFS($I$2:$I$2001,$N$2:$N$2001,"West",$D$2:$D$2001,BH2) -> 155358.84 | BK2: =_xludf.RANK.EQ(BJ2,$BJ$2:$BJ$61,0) -> #NAME? | BL2: 0 | BM2: 0 | BN2: 0.018867925 | BO2: 0 | BP2: 0
A3: =Orders!A3 -> ORD-00002 | B3: =Orders!B3 -> 45340 | C3: =Orders!C3 -> CUST-0202 | D3: =Orders!D3 -> PROD-020 | E3: =Orders!E3 -> R005 | F3: =Orders!F3 -> 2 | G3: =Orders!G3 -> 820 | H3: =Orders!H3 -> 10.8 | ... K3: =Orders!K3 -> Chennai | L3: =IFERROR(VLOOKUP(D3,Products!$A$2:$F$61,3,FALSE),"") -> Apparel | M3: =IFERROR(VLOOKUP(D3,Products!$A$2:$F$61,4,FALSE),"") -> 391 | N3: =IFERROR(VLOOKUP(E3,Sales_Reps!$A$2:$E$31,3,FALSE),"") -> North | O3: =IFERROR(VLOOKUP(C3,Customers!$A$2:$F$301,5,FALSE),"") -> Retail | P3: =IFERROR(VLOOKUP(C3,Customers!$A$2:$F$301,3,FALSE),"") -> 39 | Q3: =IFERROR((G3-M3)/G3,0) -> 0.52317073 | R3: =IFERROR(VLOOKUP(C3,Customers!$A$2:$F$301,1,FALSE),"") -> CUST-0202 | S3: =IFERROR(VLOOKUP(D3,Products!$A$2:$F$61,6,FALSE),"") -> TRUE | T3: Q1.2 | U3: =VLOOKUP(INDEX($D$2:$D$2001,MATCH("ORD-00456",$A$2:$A$2001,0)),Products!$A$2:$F$61,2,FALSE) -> Dumbbells 5kg | V3: Order product ID, then VLOOKUP | W3: =Sales_Reps!A3 -> R002 | X3: =Sales_Reps!B3 -> Sunita Malhotra | Y3: =SUMIF($E$2:$E$2001,W3,$I$2:$I$2001) -> 980063.66 | Z3: =_xludf.RANK.EQ(Y3,$Y$2:$Y$31,0) -> #NAME? | AB3: =DATE(2024,2,1) -> 45323 | AC3: =SUMIFS($I$2:$I$2001,$B$2:$B$2001,">="&$AB3,$B$2:$B$2001,"<"&EDATE($AB3,1),$E$2:$E$2001,AC$1) -> 127005.17 | AD3: =SUMIFS($I$2:$I$2001,$B$2:$B$2001,">="&$AB3,$B$2:$B$2001,"<"&EDATE($AB3,1),$E$2:$E$2001,AD$1) -> 125187.78 | AE3: =SUMIFS($I$2:$I$2001,$B$2:$B$2001,">="&$AB3,$B$2:$B$2001,"<"&EDATE($AB3,1),$E$2:$E$2001,AE$1) -> 32452 | AF3: =SUMIFS($I$2:$I$2001,$B$2:$B$2001,">="&$AB3,$B$2:$B$2001,"<"&EDATE($AB3,1),$E$2:$E$2001,AF$1) -> 58818.56 | AG3: =SUMIFS($I$2:$I$2001,$B$2:$B$2001,">="&$AB3,$B$2:$B$2001,"<"&EDATE($AB3,1),$E$2:$E$2001,AG$1) -> 57914.81 | AH3: =SUMIFS($I$2:$I$2001,$B$2:$B$2001,">="&$AB3,$B$2:$B$2001,"<"&EDATE($AB3,1),$E$2:$E$2001,AH$1) -> 34581.99 | AI3: =SUMIFS($I$2:$I$2001,$B$2:$B$2001,">="&$AB3,$B$2:$B$2001,"<"&EDATE($AB3,1),$E$2:$E$2001,AI$1) -> 130276.04 | AJ3: =SUMIFS($I$2:$I$2001,$B$2:$B$2001,">="&$AB3,$B$2:$B$2001,"<"&EDATE($AB3,1),$E$2:$E$2001,AJ$1) -> 23463.3 | ... BF3: =SUMIFS($I$2:$I$2001,$B$2:$B$2001,">="&$AB3,$B$2:$B$2001,"<"&EDATE($AB3,1),$E$2:$E$2001,BF$1) -> 17274.29 | BH3: =Products!A3 -> PROD-002 | BI3: =Products!B3 -> Wireless Earbuds | BJ3: =SUMIFS($I$2:$I$2001,$N$2:$N$2001,"West",$D$2:$D$2001,BH3) -> 105284.4 | BK3: =_xludf.RANK.EQ(BJ3,$BJ$2:$BJ$61,0) -> #NAME? | BL3: 0 | BM3: 0 | BN3: 0.018867925 | BO3: 0 | BP3: 0
A4: =Orders!A4 -> ORD-00003 | B4: =Orders!B4 -> 45371 | C4: =Orders!C4 -> CUST-0098 | D4: =Orders!D4 -> PROD-053 | E4: =Orders!E4 -> R014 | F4: =Orders!F4 -> 8 | G4: =Orders!G4 -> 470 | H4: =Orders!H4 -> 3.3 | ... K4: =Orders!K4 -> Delhi | L4: =IFERROR(VLOOKUP(D4,Products!$A$2:$F$61,3,FALSE),"") -> Sports | M4: =IFERROR(VLOOKUP(D4,Products!$A$2:$F$61,4,FALSE),"") -> 302 | N4: =IFERROR(VLOOKUP(E4,Sales_Reps!$A$2:$E$31,3,FALSE),"") -> South | O4: =IFERROR(VLOOKUP(C4,Customers!$A$2:$F$301,5,FALSE),"") -> Retail | P4: =IFERROR(VLOOKUP(C4,Customers!$A$2:$F$301,3,FALSE),"") -> 52 | Q4: =IFERROR((G4-M4)/G4,0) -> 0.35744681 | R4: =IFERROR(VLOOKUP(C4,Customers!$A$2:$F$301,1,FALSE),"") -> CUST-0098 | S4: =IFERROR(VLOOKUP(D4,Products!$A$2:$F$61,6,FALSE),"") -> FALSE | T4: Q1.3 | U4: =INDEX(Sales_Reps!$B$2:$B$31,MATCH(INDEX($E$2:$E$2001,MATCH("ORD-00987",$A$2:$A$2001,0)),Sales_Reps!$A$2:$A$31,0)) -> Nisha Menon | V4: INDEX + MATCH for rep name | W4: =Sales_Reps!A4 -> R003 | X4: =Sales_Reps!B4 -> Amit Singh | Y4: =SUMIF($E$2:$E$2001,W4,$I$2:$I$2001) -> 986692.91 | Z4: =_xludf.RANK.EQ(Y4,$Y$2:$Y$31,0) -> #NAME? | AB4: =DATE(2024,3,1) -> 45352 | AC4: =SUMIFS($I$2:$I$2001,$B$2:$B$2001,">="&$AB4,$B$2:$B$2001,"<"&EDATE($AB4,1),$E$2:$E$2001,AC$1) -> 58208.49 | AD4: =SUMIFS($I$2:$I$2001,$B$2:$B$2001,">="&$AB4,$B$2:$B$2001,"<"&EDATE($AB4,1),$E$2:$E$2001,AD$1) -> 53533 | AE4: =SUMIFS($I$2:$I$2001,$B$2:$B$2001,">="&$AB4,$B$2:$B$2001,"<"&EDATE($AB4,1),$E$2:$E$2001,AE$1) -> 107489.23 | AF4: =SUMIFS($I$2:$I$2001,$B$2:$B$2001,">="&$AB4,$B$2:$B$2001,"<"&EDATE($AB4,1),$E$2:$E$2001,AF$1) -> 14394.38 | AG4: =SUMIFS($I$2:$I$2001,$B$2:$B$2001,">="&$AB4,$B$2:$B$2001,"<"&EDATE($AB4,1),$E$2:$E$2001,AG$1) -> 85853.43 | AH4: =SUMIFS($I$2:$I$2001,$B$2:$B$2001,">="&$AB4,$B$2:$B$2001,"<"&EDATE($AB4,1),$E$2:$E$2001,AH$1) -> 145435.13 | AI4: =SUMIFS($I$2:$I$2001,$B$2:$B$2001,">="&$AB4,$B$2:$B$2001,"<"&EDATE($AB4,1),$E$2:$E$2001,AI$1) -> 105489.83 | AJ4: =SUMIFS($I$2:$I$2001,$B$2:$B$2001,">="&$AB4,$B$2:$B$2001,"<"&EDATE($AB4,1),$E$2:$E$2001,AJ$1) -> 164615.05 | ... BF4: =SUMIFS($I$2:$I$2001,$B$2:$B$2001,">="&$AB4,$B$2:$B$2001,"<"&EDATE($AB4,1),$E$2:$E$2001,BF$1) -> 122041.06 | BH4: =Products!A4 -> PROD-003 | BI4: =Products!B4 -> Smart Watch | BJ4: =SUMIFS($I$2:$I$2001,$N$2:$N$2001,"West",$D$2:$D$2001,BH4) -> 248025.75 | BK4: =_xludf.RANK.EQ(BJ4,$BJ$2:$BJ$61,0) -> #NAME? | BL4: 0 | BM4: 0 | BN4: 0.018518519 | BO4: 0 | BP4: 1
A5: =Orders!A5 -> ORD-00004 | B5: =Orders!B5 -> 45413 | C5: =Orders!C5 -> CUST-0071 | D5: =Orders!D5 -> PROD-028 | E5: =Orders!E5 -> R006 | F5: =Orders!F5 -> 1 | G5: =Orders!G5 -> 3660 | H5: =Orders!H5 -> 15.7 | ... K5: =Orders!K5 -> Delhi | L5: =IFERROR(VLOOKUP(D5,Products!$A$2:$F$61,3,FALSE),"") -> Grocery | M5: =IFERROR(VLOOKUP(D5,Products!$A$2:$F$61,4,FALSE),"") -> 2214 | N5: =IFERROR(VLOOKUP(E5,Sales_Reps!$A$2:$E$31,3,FALSE),"") -> North | O5: =IFERROR(VLOOKUP(C5,Customers!$A$2:$F$301,5,FALSE),"") -> Corporate | P5: =IFERROR(VLOOKUP(C5,Customers!$A$2:$F$301,3,FALSE),"") -> 46 | Q5: =IFERROR((G5-M5)/G5,0) -> 0.39508197 | R5: =IFERROR(VLOOKUP(C5,Customers!$A$2:$F$301,1,FALSE),"") -> CUST-0071 | S5: =IFERROR(VLOOKUP(D5,Products!$A$2:$F$61,6,FALSE),"") -> FALSE | T5: Q1.4 | U5: =INDEX(Targets!$A$2:$M$31,MATCH("R012",Targets!$A$2:$A$31,0),MATCH("Mar-24",Targets!$A$1:$M$1,0)) -> 321255 | V5: Two-way INDEX + MATCH | W5: =Sales_Reps!A5 -> R004 | X5: =Sales_Reps!B5 -> Priya Singh | Y5: =SUMIF($E$2:$E$2001,W5,$I$2:$I$2001) -> 589026.29 | Z5: =_xludf.RANK.EQ(Y5,$Y$2:$Y$31,0) -> #NAME? | AB5: =DATE(2024,4,1) -> 45383 | AC5: =SUMIFS($I$2:$I$2001,$B$2:$B$2001,">="&$AB5,$B$2:$B$2001,"<"&EDATE($AB5,1),$E$2:$E$2001,AC$1) -> 33643.48 | AD5: =SUMIFS($I$2:$I$2001,$B$2:$B$2001,">="&$AB5,$B$2:$B$2001,"<"&EDATE($AB5,1),$E$2:$E$2001,AD$1) -> 46286.92 | AE5: =SUMIFS($I$2:$I$2001,$B$2:$B$2001,">="&$AB5,$B$2:$B$2001,"<"&EDATE($AB5,1),$E$2:$E$2001,AE$1) -> 96349.86 | AF5: =SUMIFS($I$2:$I$2001,$B$2:$B$2001,">="&$AB5,$B$2:$B$2001,"<"&EDATE($AB5,1),$E$2:$E$2001,AF$1) -> 23036.54 | AG5: =SUMIFS($I$2:$I$2001,$B$2:$B$2001,">="&$AB5,$B$2:$B$2001,"<"&EDATE($AB5,1),$E$2:$E$2001,AG$1) -> 46025.56 | AH5: =SUMIFS($I$2:$I$2001,$B$2:$B$2001,">="&$AB5,$B$2:$B$2001,"<"&EDATE($AB5,1),$E$2:$E$2001,AH$1) -> 170939.91 | AI5: =SUMIFS($I$2:$I$2001,$B$2:$B$2001,">="&$AB5,$B$2:$B$2001,"<"&EDATE($AB5,1),$E$2:$E$2001,AI$1) -> 48536.18 | AJ5: =SUMIFS($I$2:$I$2001,$B$2:$B$2001,">="&$AB5,$B$2:$B$2001,"<"&EDATE($AB5,1),$E$2:$E$2001,AJ$1) -> 12044.56 | ... BF5: =SUMIFS($I$2:$I$2001,$B$2:$B$2001,">="&$AB5,$B$2:$B$2001,"<"&EDATE($AB5,1),$E$2:$E$2001,BF$1) -> 36350.86 | BH5: =Products!A5 -> PROD-004 | BI5: =Products!B5 -> Laptop Bag | BJ5: =SUMIFS($I$2:$I$2001,$N$2:$N$2001,"West",$D$2:$D$2001,BH5) -> 198124.65 | BK5: =_xludf.RANK.EQ(BJ5,$BJ$2:$BJ$61,0) -> #NAME? | BL5: 0 | BM5: 0 | BN5: 0.023809524 | BO5: 0 | BP5: 1
A6: =Orders!A6 -> ORD-00005 | B6: =Orders!B6 -> 45611 | C6: =Orders!C6 -> CUST-0180 | D6: =Orders!D6 -> PROD-012 | E6: =Orders!E6 -> R008 | F6: =Orders!F6 -> 1 | G6: =Orders!G6 -> 3160 | H6: =Orders!H6 -> 26 | ... K6: =Orders!K6 -> Chennai | L6: =IFERROR(VLOOKUP(D6,Products!$A$2:$F$61,3,FALSE),"") -> Apparel | M6: =IFERROR(VLOOKUP(D6,Products!$A$2:$F$61,4,FALSE),"") -> 1886 | N6: =IFERROR(VLOOKUP(E6,Sales_Reps!$A$2:$E$31,3,FALSE),"") -> North | O6: =IFERROR(VLOOKUP(C6,Customers!$A$2:$F$301,5,FALSE),"") -> Retail | P6: =IFERROR(VLOOKUP(C6,Customers!$A$2:$F$301,3,FALSE),"") -> 36 | Q6: =IFERROR((G6-M6)/G6,0) -> 0.40316456 | R6: =IFERROR(VLOOKUP(C6,Customers!$A$2:$F$301,1,FALSE),"") -> CUST-0180 | S6: =IFERROR(VLOOKUP(D6,Products!$A$2:$F$61,6,FALSE),"") -> TRUE | T6: Q1.5 | U6: =VLOOKUP(INDEX($D$2:$D$2001,MATCH("ORD-01500",$A$2:$A$2001,0)),Products!$A$2:$F$61,3,FALSE) -> Electronics | V6: Chain lookup | W6: =Sales_Reps!A6 -> R005 | X6: =Sales_Reps!B6 -> Vikram Patel | Y6: =SUMIF($E$2:$E$2001,W6,$I$2:$I$2001) -> 782445.33 | Z6: =_xludf.RANK.EQ(Y6,$Y$2:$Y$31,0) -> #NAME? | AB6: =DATE(2024,5,1) -> 45413 | AC6: =SUMIFS($I$2:$I$2001,$B$2:$B$2001,">="&$AB6,$B$2:$B$2001,"<"&EDATE($AB6,1),$E$2:$E$2001,AC$1) -> 44809.66 | AD6: =SUMIFS($I$2:$I$2001,$B$2:$B$2001,">="&$AB6,$B$2:$B$2001,"<"&EDATE($AB6,1),$E$2:$E$2001,AD$1) -> 89794.86 | AE6: =SUMIFS($I$2:$I$2001,$B$2:$B$2001,">="&$AB6,$B$2:$B$2001,"<"&EDATE($AB6,1),$E$2:$E$2001,AE$1) -> 139257.72 | AF6: =SUMIFS($I$2:$I$2001,$B$2:$B$2001,">="&$AB6,$B$2:$B$2001,"<"&EDATE($AB6,1),$E$2:$E$2001,AF$1) -> 140739.8 | AG6: =SUMIFS($I$2:$I$2001,$B$2:$B$2001,">="&$AB6,$B$2:$B$2001,"<"&EDATE($AB6,1),$E$2:$E$2001,AG$1) -> 67702.82 | AH6: =SUMIFS($I$2:$I$2001,$B$2:$B$2001,">="&$AB6,$B$2:$B$2001,"<"&EDATE($AB6,1),$E$2:$E$2001,AH$1) -> 78322.48 | AI6: =SUMIFS($I$2:$I$2001,$B$2:$B$2001,">="&$AB6,$B$2:$B$2001,"<"&EDATE($AB6,1),$E$2:$E$2001,AI$1) -> 41157.84 | AJ6: =SUMIFS($I$2:$I$2001,$B$2:$B$2001,">="&$AB6,$B$2:$B$2001,"<"&EDATE($AB6,1),$E$2:$E$2001,AJ$1) -> 67200.57 | ... BF6: =SUMIFS($I$2:$I$2001,$B$2:$B$2001,">="&$AB6,$B$2:$B$2001,"<"&EDATE($AB6,1),$E$2:$E$2001,BF$1) -> 47579.17 | BH6: =Products!A6 -> PROD-005 | BI6: =Products!B6 -> Power Bank | BJ6: =SUMIFS($I$2:$I$2001,$N$2:$N$2001,"West",$D$2:$D$2001,BH6) -> 7449.9 | BK6: =_xludf.RANK.EQ(BJ6,$BJ$2:$BJ$61,0) -> #NAME? | BL6: 0 | BM6: 0 | BN6: 0.018867925 | BO6: 0 | BP6: 0
A7: =Orders!A7 -> ORD-00006 | B7: =Orders!B7 -> 45406 | C7: =Orders!C7 -> CUST-0275 | D7: =Orders!D7 -> PROD-032 | E7: =Orders!E7 -> R025 | F7: =Orders!F7 -> 4 | G7: =Orders!G7 -> 370 | H7: =Orders!H7 -> 29 | ... K7: =Orders!K7 -> Mumbai | L7: =IFERROR(VLOOKUP(D7,Products!$A$2:$F$61,3,FALSE),"") -> Home | M7: =IFERROR(VLOOKUP(D7,Products!$A$2:$F$61,4,FALSE),"") -> 288 | N7: =IFERROR(VLOOKUP(E7,Sales_Reps!$A$2:$E$31,3,FALSE),"") -> West | O7: =IFERROR(VLOOKUP(C7,Customers!$A$2:$F$301,5,FALSE),"") -> Retail | P7: =IFERROR(VLOOKUP(C7,Customers!$A$2:$F$301,3,FALSE),"") -> 36 | Q7: =IFERROR((G7-M7)/G7,0) -> 0.22162162 | R7: =IFERROR(VLOOKUP(C7,Customers!$A$2:$F$301,1,FALSE),"") -> CUST-0275 | S7: =IFERROR(VLOOKUP(D7,Products!$A$2:$F$61,6,FALSE),"") -> TRUE | T7: Q1.6 | U7: =VLOOKUP(INDEX($H$2:$H$2001,MATCH("ORD-00789",$A$2:$A$2001,0)),Q1_Lookups!$B$18:$C$21,2,TRUE) -> Bronze | V7: Approximate VLOOKUP | W7: =Sales_Reps!A7 -> R006 | X7: =Sales_Reps!B7 -> Neha Desai | Y7: =SUMIF($E$2:$E$2001,W7,$I$2:$I$2001) -> 1138648.7 | Z7: =_xludf.RANK.EQ(Y7,$Y$2:$Y$31,0) -> #NAME? | AB7: =DATE(2024,6,1) -> 45444 | AC7: =SUMIFS($I$2:$I$2001,$B$2:$B$2001,">="&$AB7,$B$2:$B$2001,"<"&EDATE($AB7,1),$E$2:$E$2001,AC$1) -> 82789.95 | AD7: =SUMIFS($I$2:$I$2001,$B$2:$B$2001,">="&$AB7,$B$2:$B$2001,"<"&EDATE($AB7,1),$E$2:$E$2001,AD$1) -> 82753.37 | AE7: =SUMIFS($I$2:$I$2001,$B$2:$B$2001,">="&$AB7,$B$2:$B$2001,"<"&EDATE($AB7,1),$E$2:$E$2001,AE$1) -> 37966.09 | AF7: =SUMIFS($I$2:$I$2001,$B$2:$B$2001,">="&$AB7,$B$2:$B$2001,"<"&EDATE($AB7,1),$E$2:$E$2001,AF$1) -> 42388.12 | AG7: =SUMIFS($I$2:$I$2001,$B$2:$B$2001,">="&$AB7,$B$2:$B$2001,"<"&EDATE($AB7,1),$E$2:$E$2001,AG$1) -> 113205.32 | AH7: =SUMIFS($I$2:$I$2001,$B$2:$B$2001,">="&$AB7,$B$2:$B$2001,"<"&EDATE($AB7,1),$E$2:$E$2001,AH$1) -> 191251.6 | AI7: =SUMIFS($I$2:$I$2001,$B$2:$B$2001,">="&$AB7,$B$2:$B$2001,"<"&EDATE($AB7,1),$E$2:$E$2001,AI$1) -> 58895.11 | AJ7: =SUMIFS($I$2:$I$2001,$B$2:$B$2001,">="&$AB7,$B$2:$B$2001,"<"&EDATE($AB7,1),$E$2:$E$2001,AJ$1) -> 82481.44 | ... BF7: =SUMIFS($I$2:$I$2001,$B$2:$B$2001,">="&$AB7,$B$2:$B$2001,"<"&EDATE($AB7,1),$E$2:$E$2001,BF$1) -> 67486.9 | BH7: =Products!A7 -> PROD-006 | BI7: =Products!B7 -> Bluetooth Speaker | BJ7: =SUMIFS($I$2:$I$2001,$N$2:$N$2001,"West",$D$2:$D$2001,BH7) -> 100869.76 | BK7: =_xludf.RANK.EQ(BJ7,$BJ$2:$BJ$61,0) -> #NAME? | BL7: 0 | BM7: 0 | BN7: 0.018867925 | BO7: 0 | BP7: 0
A8: =Orders!A8 -> ORD-00007 | B8: =Orders!B8 -> 45455 | C8: =Orders!C8 -> CUST-0293 | D8: =Orders!D8 -> PROD-057 | E8: =Orders!E8 -> R024 | F8: =Orders!F8 -> 3 | G8: =Orders!G8 -> 960 | H8: =Orders!H8 -> 5.8 | ... K8: =Orders!K8 -> Bengaluru | L8: =IFERROR(VLOOKUP(D8,Products!$A$2:$F$61,3,FALSE),"") -> Sports | M8: =IFERROR(VLOOKUP(D8,Products!$A$2:$F$61,4,FALSE),"") -> 705 | N8: =IFERROR(VLOOKUP(E8,Sales_Reps!$A$2:$E$31,3,FALSE),"") -> West | O8: =IFERROR(VLOOKUP(C8,Customers!$A$2:$F$301,5,FALSE),"") -> Retail | P8: =IFERROR(VLOOKUP(C8,Customers!$A$2:$F$301,3,FALSE),"") -> 27 | Q8: =IFERROR((G8-M8)/G8,0) -> 0.265625 | R8: =IFERROR(VLOOKUP(C8,Customers!$A$2:$F$301,1,FALSE),"") -> CUST-0293 | S8: =IFERROR(VLOOKUP(D8,Products!$A$2:$F$61,6,FALSE),"") -> TRUE | T8: Q1.7 | U8: =INDEX(Sales_Reps!$B$2:$B$31,MATCH(INDEX($E$2:$E$2001,MATCH("ORD-01234",$A$2:$A$2001,0)),Sales_Reps!$A$2:$A$31,0))&" ("&INDEX(Sales_Reps!$C$2:$C$31,MATCH(INDEX($E$2:$E$2001,MATCH("ORD-01234",$A$2:$A$2001,0)),Sales_Reps!$A$2:$A$31,0))&")" -> Sanjay Kapoor (South) | V8: Two lookups joined with & | W8: =Sales_Reps!A8 -> R007 | X8: =Sales_Reps!B8 -> Suresh Menon | Y8: =SUMIF($E$2:$E$2001,W8,$I$2:$I$2001) -> 855749.68 | Z8: =_xludf.RANK.EQ(Y8,$Y$2:$Y$31,0) -> #NAME? | AB8: =DATE(2024,7,1) -> 45474 | AC8: =SUMIFS($I$2:$I$2001,$B$2:$B$2001,">="&$AB8,$B$2:$B$2001,"<"&EDATE($AB8,1),$E$2:$E$2001,AC$1) -> 28761.2 | AD8: =SUMIFS($I$2:$I$2001,$B$2:$B$2001,">="&$AB8,$B$2:$B$2001,"<"&EDATE($AB8,1),$E$2:$E$2001,AD$1) -> 62949.74 | AE8: =SUMIFS($I$2:$I$2001,$B$2:$B$2001,">="&$AB8,$B$2:$B$2001,"<"&EDATE($AB8,1),$E$2:$E$2001,AE$1) -> 185921.75 | AF8: =SUMIFS($I$2:$I$2001,$B$2:$B$2001,">="&$AB8,$B$2:$B$2001,"<"&EDATE($AB8,1),$E$2:$E$2001,AF$1) -> 7823.48 | AG8: =SUMIFS($I$2:$I$2001,$B$2:$B$2001,">="&$AB8,$B$2:$B$2001,"<"&EDATE($AB8,1),$E$2:$E$2001,AG$1) -> 20649.35 | AH8: =SUMIFS($I$2:$I$2001,$B$2:$B$2001,">="&$AB8,$B$2:$B$2001,"<"&EDATE($AB8,1),$E$2:$E$2001,AH$1) -> 38479.32 | AI8: =SUMIFS($I$2:$I$2001,$B$2:$B$2001,">="&$AB8,$B$2:$B$2001,"<"&EDATE($AB8,1),$E$2:$E$2001,AI$1) -> 11528.24 | AJ8: =SUMIFS($I$2:$I$2001,$B$2:$B$2001,">="&$AB8,$B$2:$B$2001,"<"&EDATE($AB8,1),$E$2:$E$2001,AJ$1) -> 75853.47 | ... BF8: =SUMIFS($I$2:$I$2001,$B$2:$B$2001,">="&$AB8,$B$2:$B$2001,"<"&EDATE($AB8,1),$E$2:$E$2001,BF$1) -> 89271.18 | BH8: =Products!A8 -> PROD-007 | BI8: =Products!B8 -> USB-C Cable | BJ8: =SUMIFS($I$2:$I$2001,$N$2:$N$2001,"West",$D$2:$D$2001,BH8) -> 38531.35 | BK8: =_xludf.RANK.EQ(BJ8,$BJ$2:$BJ$61,0) -> #NAME? | BL8: 0 | BM8: 0 | BN8: 0.021276596 | BO8: 0 | BP8: 0
A9: =Orders!A9 -> ORD-00008 | B9: =Orders!B9 -> 45617 | C9: =Orders!C9 -> CUST-0281 | D9: =Orders!D9 -> PROD-007 | E9: =Orders!E9 -> R019 | F9: =Orders!F9 -> 8 | G9: =Orders!G9 -> 1430 | H9: =Orders!H9 -> 2.4 | ... K9: =Orders!K9 -> Bengaluru | L9: =IFERROR(VLOOKUP(D9,Products!$A$2:$F$61,3,FALSE),"") -> Electronics | M9: =IFERROR(VLOOKUP(D9,Products!$A$2:$F$61,4,FALSE),"") -> 861 | N9: =IFERROR(VLOOKUP(E9,Sales_Reps!$A$2:$E$31,3,FALSE),"") -> East | O9: =IFERROR(VLOOKUP(C9,Customers!$A$2:$F$301,5,FALSE),"") -> Corporate | P9: =IFERROR(VLOOKUP(C9,Customers!$A$2:$F$301,3,FALSE),"") -> 57 | Q9: =IFERROR((G9-M9)/G9,0) -> 0.3979021 | R9: =IFERROR(VLOOKUP(C9,Customers!$A$2:$F$301,1,FALSE),"") -> CUST-0281 | S9: =IFERROR(VLOOKUP(D9,Products!$A$2:$F$61,6,FALSE),"") -> TRUE | T9: Q1.8 | U9: =INDEX(Sales_Reps!$B$2:$B$31,MATCH(INDEX(Sales_Reps!$E$2:$E$31,MATCH("R017",Sales_Reps!$A$2:$A$31,0)),Sales_Reps!$A$2:$A$31,0)) -> Amit Singh | V9: Self lookup | W9: =Sales_Reps!A9 -> R008 | X9: =Sales_Reps!B9 -> Kavita Patel | Y9: =SUMIF($E$2:$E$2001,W9,$I$2:$I$2001) -> 861553.33 | Z9: =_xludf.RANK.EQ(Y9,$Y$2:$Y$31,0) -> #NAME? | AB9: =DATE(2024,8,1) -> 45505 | AC9: =SUMIFS($I$2:$I$2001,$B$2:$B$2001,">="&$AB9,$B$2:$B$2001,"<"&EDATE($AB9,1),$E$2:$E$2001,AC$1) -> 92676.92 | AD9: =SUMIFS($I$2:$I$2001,$B$2:$B$2001,">="&$AB9,$B$2:$B$2001,"<"&EDATE($AB9,1),$E$2:$E$2001,AD$1) -> 134500.5 | AE9: =SUMIFS($I$2:$I$2001,$B$2:$B$2001,">="&$AB9,$B$2:$B$2001,"<"&EDATE($AB9,1),$E$2:$E$2001,AE$1) -> 114656.27 | AF9: =SUMIFS($I$2:$I$2001,$B$2:$B$2001,">="&$AB9,$B$2:$B$2001,"<"&EDATE($AB9,1),$E$2:$E$2001,AF$1) -> 55975.34 | AG9: =SUMIFS($I$2:$I$2001,$B$2:$B$2001,">="&$AB9,$B$2:$B$2001,"<"&EDATE($AB9,1),$E$2:$E$2001,AG$1) -> 15060.28 | AH9: =SUMIFS($I$2:$I$2001,$B$2:$B$2001,">="&$AB9,$B$2:$B$2001,"<"&EDATE($AB9,1),$E$2:$E$2001,AH$1) -> 61857.9 | AI9: =SUMIFS($I$2:$I$2001,$B$2:$B$2001,">="&$AB9,$B$2:$B$2001,"<"&EDATE($AB9,1),$E$2:$E$2001,AI$1) -> 70196.8 | AJ9: =SUMIFS($I$2:$I$2001,$B$2:$B$2001,">="&$AB9,$B$2:$B$2001,"<"&EDATE($AB9,1),$E$2:$E$2001,AJ$1) -> 61043.44 | ... BF9: =SUMIFS($I$2:$I$2001,$B$2:$B$2001,">="&$AB9,$B$2:$B$2001,"<"&EDATE($AB9,1),$E$2:$E$2001,BF$1) -> 74000.9 | BH9: =Products!A9 -> PROD-008 | BI9: =Products!B9 -> Wireless Mouse | BJ9: =SUMIFS($I$2:$I$2001,$N$2:$N$2001,"West",$D$2:$D$2001,BH9) -> 7807.1 | BK9: =_xludf.RANK.EQ(BJ9,$BJ$2:$BJ$61,0) -> #NAME? | BL9: 0 | BM9: 0 | BN9: 0.018867925 | BO9: 0 | BP9: 0
A10: =Orders!A10 -> ORD-00009 | B10: =Orders!B10 -> 45549 | C10: =Orders!C10 -> CUST-0260 | D10: =Orders!D10 -> PROD-038 | E10: =Orders!E10 -> R008 | F10: =Orders!F10 -> 3 | G10: =Orders!G10 -> 5490 | H10: =Orders!H10 -> 14.2 | ... K10: =Orders!K10 -> Bengaluru | L10: =IFERROR(VLOOKUP(D10,Products!$A$2:$F$61,3,FALSE),"") -> Home | M10: =IFERROR(VLOOKUP(D10,Products!$A$2:$F$61,4,FALSE),"") -> 2549 | N10: =IFERROR(VLOOKUP(E10,Sales_Reps!$A$2:$E$31,3,FALSE),"") -> North | O10: =IFERROR(VLOOKUP(C10,Customers!$A$2:$F$301,5,FALSE),"") -> Retail | P10: =IFERROR(VLOOKUP(C10,Customers!$A$2:$F$301,3,FALSE),"") -> 42 | Q10: =IFERROR((G10-M10)/G10,0) -> 0.53570128 | R10: =IFERROR(VLOOKUP(C10,Customers!$A$2:$F$301,1,FALSE),"") -> CUST-0260 | S10: =IFERROR(VLOOKUP(D10,Products!$A$2:$F$61,6,FALSE),"") -> TRUE | T10: Q2.1 | U10: 20 | V10: Row-by-row duplicate check | W10: =Sales_Reps!A10 -> R009 | X10: =Sales_Reps!B10 -> Manoj Patel | Y10: =SUMIF($E$2:$E$2001,W10,$I$2:$I$2001) -> 914554.72 | Z10: =_xludf.RANK.EQ(Y10,$Y$2:$Y$31,0) -> #NAME? | AB10: =DATE(2024,9,1) -> 45536 | AC10: =SUMIFS($I$2:$I$2001,$B$2:$B$2001,">="&$AB10,$B$2:$B$2001,"<"&EDATE($AB10,1),$E$2:$E$2001,AC$1) -> 88884.34 | AD10: =SUMIFS($I$2:$I$2001,$B$2:$B$2001,">="&$AB10,$B$2:$B$2001,"<"&EDATE($AB10,1),$E$2:$E$2001,AD$1) -> 91647.29 | AE10: =SUMIFS($I$2:$I$2001,$B$2:$B$2001,">="&$AB10,$B$2:$B$2001,"<"&EDATE($AB10,1),$E$2:$E$2001,AE$1) -> 69896.72 | AF10: =SUMIFS($I$2:$I$2001,$B$2:$B$2001,">="&$AB10,$B$2:$B$2001,"<"&EDATE($AB10,1),$E$2:$E$2001,AF$1) -> 46944.28 | AG10: =SUMIFS($I$2:$I$2001,$B$2:$B$2001,">="&$AB10,$B$2:$B$2001,"<"&EDATE($AB10,1),$E$2:$E$2001,AG$1) -> 81963.69 | AH10: =SUMIFS($I$2:$I$2001,$B$2:$B$2001,">="&$AB10,$B$2:$B$2001,"<"&EDATE($AB10,1),$E$2:$E$2001,AH$1) -> 76627.83 | AI10: =SUMIFS($I$2:$I$2001,$B$2:$B$2001,">="&$AB10,$B$2:$B$2001,"<"&EDATE($AB10,1),$E$2:$E$2001,AI$1) -> 52194.15 | AJ10: =SUMIFS($I$2:$I$2001,$B$2:$B$2001,">="&$AB10,$B$2:$B$2001,"<"&EDATE($AB10,1),$E$2:$E$2001,AJ$1) -> 49404.64 | ... BF10: =SUMIFS($I$2:$I$2001,$B$2:$B$2001,">="&$AB10,$B$2:$B$2001,"<"&EDATE($AB10,1),$E$2:$E$2001,BF$1) -> 26448.21 | BH10: =Products!A10 -> PROD-009 | BI10: =Products!B10 -> Mechanical Keyboard | BJ10: =SUMIFS($I$2:$I$2001,$N$2:$N$2001,"West",$D$2:$D$2001,BH10) -> 64207.38 | BK10: =_xludf.RANK.EQ(BJ10,$BJ$2:$BJ$61,0) -> #NAME? | BL10: 0 | BM10: 0 | BN10: 0.018518519 | BO10: 0 | BP10: 0
A11: =Orders!A11 -> ORD-00010 | B11: =Orders!B11 -> 45396 | C11: =Orders!C11 -> CUST-0147 | D11: =Orders!D11 -> PROD-030 | E11: =Orders!E11 -> R028 | F11: =Orders!F11 -> 3 | G11: =Orders!G11 -> 970 | H11: =Orders!H11 -> 1.2 | ... K11: =Orders!K11 -> Pune | L11: =IFERROR(VLOOKUP(D11,Products!$A$2:$F$61,3,FALSE),"") -> Grocery | M11: =IFERROR(VLOOKUP(D11,Products!$A$2:$F$61,4,FALSE),"") -> 434 | N11: =IFERROR(VLOOKUP(E11,Sales_Reps!$A$2:$E$31,3,FALSE),"") -> West | O11: =IFERROR(VLOOKUP(C11,Customers!$A$2:$F$301,5,FALSE),"") -> Retail | P11: =IFERROR(VLOOKUP(C11,Customers!$A$2:$F$301,3,FALSE),"") -> 56 | Q11: =IFERROR((G11-M11)/G11,0) -> 0.55257732 | R11: =IFERROR(VLOOKUP(C11,Customers!$A$2:$F$301,1,FALSE),"") -> CUST-0147 | S11: =IFERROR(VLOOKUP(D11,Products!$A$2:$F$61,6,FALSE),"") -> TRUE | T11: Q2.2 | U11: 15 | V11: LEN vs TRIM helper | W11: =Sales_Reps!A11 -> R010 | X11: =Sales_Reps!B11 -> Divya Rao | Y11: =SUMIF($E$2:$E$2001,W11,$I$2:$I$2001) -> 880345.2 | Z11: =_xludf.RANK.EQ(Y11,$Y$2:$Y$31,0) -> #NAME? | AB11: =DATE(2024,10,1) -> 45566 | AC11: =SUMIFS($I$2:$I$2001,$B$2:$B$2001,">="&$AB11,$B$2:$B$2001,"<"&EDATE($AB11,1),$E$2:$E$2001,AC$1) -> 37753.9 | AD11: =SUMIFS($I$2:$I$2001,$B$2:$B$2001,">="&$AB11,$B$2:$B$2001,"<"&EDATE($AB11,1),$E$2:$E$2001,AD$1) -> 35751.81 | AE11: =SUMIFS($I$2:$I$2001,$B$2:$B$2001,">="&$AB11,$B$2:$B$2001,"<"&EDATE($AB11,1),$E$2:$E$2001,AE$1) -> 29309.98 | AF11: =SUMIFS($I$2:$I$2001,$B$2:$B$2001,">="&$AB11,$B$2:$B$2001,"<"&EDATE($AB11,1),$E$2:$E$2001,AF$1) -> 43456.18 | AG11: =SUMIFS($I$2:$I$2001,$B$2:$B$2001,">="&$AB11,$B$2:$B$2001,"<"&EDATE($AB11,1),$E$2:$E$2001,AG$1) -> 99252.77 | AH11: =SUMIFS($I$2:$I$2001,$B$2:$B$2001,">="&$AB11,$B$2:$B$2001,"<"&EDATE($AB11,1),$E$2:$E$2001,AH$1) -> 52942.27 | AI11: =SUMIFS($I$2:$I$2001,$B$2:$B$2001,">="&$AB11,$B$2:$B$2001,"<"&EDATE($AB11,1),$E$2:$E$2001,AI$1) -> 57313.75 | AJ11: =SUMIFS($I$2:$I$2001,$B$2:$B$2001,">="&$AB11,$B$2:$B$2001,"<"&EDATE($AB11,1),$E$2:$E$2001,AJ$1) -> 26620.46 | ... BF11: =SUMIFS($I$2:$I$2001,$B$2:$B$2001,">="&$AB11,$B$2:$B$2001,"<"&EDATE($AB11,1),$E$2:$E$2001,BF$1) -> 40669.76 | BH11: =Products!A11 -> PROD-010 | BI11: =Products!B11 -> Tablet Stand | BJ11: =SUMIFS($I$2:$I$2001,$N$2:$N$2001,"West",$D$2:$D$2001,BH11) -> 67393.92 | BK11: =_xludf.RANK.EQ(BJ11,$BJ$2:$BJ$61,0) -> #NAME? | BL11: 0 | BM11: 0 | BN11: 0.018518519 | BO11: 0 | BP11: 0
A12: =Orders!A12 -> ORD-00011 | B12: =Orders!B12 -> 45560 | C12: =Orders!C12 -> CUST-0204 | D12: =Orders!D12 -> PROD-024 | E12: =Orders!E12 -> R010 | F12: =Orders!F12 -> 7 | G12: =Orders!G12 -> 2270 | H12: =Orders!H12 -> 7.1 | ... K12: =Orders!K12 -> Hyderabad | L12: =IFERROR(VLOOKUP(D12,Products!$A$2:$F$61,3,FALSE),"") -> Grocery | M12: =IFERROR(VLOOKUP(D12,Products!$A$2:$F$61,4,FALSE),"") -> 1203 | N12: =IFERROR(VLOOKUP(E12,Sales_Reps!$A$2:$E$31,3,FALSE),"") -> South | O12: =IFERROR(VLOOKUP(C12,Customers!$A$2:$F$301,5,FALSE),"") -> Retail | P12: =IFERROR(VLOOKUP(C12,Customers!$A$2:$F$301,3,FALSE),"") -> 60 | Q12: =IFERROR((G12-M12)/G12,0) -> 0.47004405 | R12: =IFERROR(VLOOKUP(C12,Customers!$A$2:$F$301,1,FALSE),"") -> CUST-0204 | S12: =IFERROR(VLOOKUP(D12,Products!$A$2:$F$61,6,FALSE),"") -> TRUE | T12: Q2.3 | U12: 6 | V12: Case-insensitive city helper | W12: =Sales_Reps!A12 -> R011 | X12: =Sales_Reps!B12 -> Anil Verma | Y12: =SUMIF($E$2:$E$2001,W12,$I$2:$I$2001) -> 735207.76 | Z12: =_xludf.RANK.EQ(Y12,$Y$2:$Y$31,0) -> #NAME? | AB12: =DATE(2024,11,1) -> 45597 | AC12: =SUMIFS($I$2:$I$2001,$B$2:$B$2001,">="&$AB12,$B$2:$B$2001,"<"&EDATE($AB12,1),$E$2:$E$2001,AC$1) -> 72215.41 | AD12: =SUMIFS($I$2:$I$2001,$B$2:$B$2001,">="&$AB12,$B$2:$B$2001,"<"&EDATE($AB12,1),$E$2:$E$2001,AD$1) -> 158277.82 | AE12: =SUMIFS($I$2:$I$2001,$B$2:$B$2001,">="&$AB12,$B$2:$B$2001,"<"&EDATE($AB12,1),$E$2:$E$2001,AE$1) -> 106760.75 | AF12: =SUMIFS($I$2:$I$2001,$B$2:$B$2001,">="&$AB12,$B$2:$B$2001,"<"&EDATE($AB12,1),$E$2:$E$2001,AF$1) -> 38491.18 | AG12: =SUMIFS($I$2:$I$2001,$B$2:$B$2001,">="&$AB12,$B$2:$B$2001,"<"&EDATE($AB12,1),$E$2:$E$2001,AG$1) -> 55570.99 | AH12: =SUMIFS($I$2:$I$2001,$B$2:$B$2001,">="&$AB12,$B$2:$B$2001,"<"&EDATE($AB12,1),$E$2:$E$2001,AH$1) -> 81500.24 | AI12: =SUMIFS($I$2:$I$2001,$B$2:$B$2001,">="&$AB12,$B$2:$B$2001,"<"&EDATE($AB12,1),$E$2:$E$2001,AI$1) -> 130208.9 | AJ12: =SUMIFS($I$2:$I$2001,$B$2:$B$2001,">="&$AB12,$B$2:$B$2001,"<"&EDATE($AB12,1),$E$2:$E$2001,AJ$1) -> 64537.26 | ... BF12: =SUMIFS($I$2:$I$2001,$B$2:$B$2001,">="&$AB12,$B$2:$B$2001,"<"&EDATE($AB12,1),$E$2:$E$2001,BF$1) -> 119624.49 | BH12: =Products!A12 -> PROD-011 | BI12: =Products!B12 -> Cotton T-Shirt | BJ12: =SUMIFS($I$2:$I$2001,$N$2:$N$2001,"West",$D$2:$D$2001,BH12) -> 145224.3 | BK12: =_xludf.RANK.EQ(BJ12,$BJ$2:$BJ$61,0) -> #NAME? | BL12: 0 | BM12: 0 | BN12: 0.018867925 | BO12: 0 | BP12: 0
A13: =Orders!A13 -> ORD-00012 | B13: =Orders!B13 -> 45332 | C13: =Orders!C13 -> CUST-0147 | D13: =Orders!D13 -> PROD-010 | E13: =Orders!E13 -> R024 | F13: =Orders!F13 -> 9 | G13: =Orders!G13 -> 2640 | H13: =Orders!H13 -> 21.7 | ... K13: =Orders!K13 -> Pune | L13: =IFERROR(VLOOKUP(D13,Products!$A$2:$F$61,3,FALSE),"") -> Electronics | M13: =IFERROR(VLOOKUP(D13,Products!$A$2:$F$61,4,FALSE),"") -> 1149 | N13: =IFERROR(VLOOKUP(E13,Sales_Reps!$A$2:$E$31,3,FALSE),"") -> West | O13: =IFERROR(VLOOKUP(C13,Customers!$A$2:$F$301,5,FALSE),"") -> Retail | P13: =IFERROR(VLOOKUP(C13,Customers!$A$2:$F$301,3,FALSE),"") -> 56 | Q13: =IFERROR((G13-M13)/G13,0) -> 0.56477273 | R13: =IFERROR(VLOOKUP(C13,Customers!$A$2:$F$301,1,FALSE),"") -> CUST-0147 | S13: =IFERROR(VLOOKUP(D13,Products!$A$2:$F$61,6,FALSE),"") -> TRUE | T13: Q2.4 | U13: 30 | V13: Missing customer helper | W13: =Sales_Reps!A13 -> R012 | X13: =Sales_Reps!B13 -> Pooja Nair | Y13: =SUMIF($E$2:$E$2001,W13,$I$2:$I$2001) -> 901394.32 | Z13: =_xludf.RANK.EQ(Y13,$Y$2:$Y$31,0) -> #NAME? | AB13: =DATE(2024,12,1) -> 45627 | AC13: =SUMIFS($I$2:$I$2001,$B$2:$B$2001,">="&$AB13,$B$2:$B$2001,"<"&EDATE($AB13,1),$E$2:$E$2001,AC$1) -> 79450.52 | AD13: =SUMIFS($I$2:$I$2001,$B$2:$B$2001,">="&$AB13,$B$2:$B$2001,"<"&EDATE($AB13,1),$E$2:$E$2001,AD$1) -> 47673.25 | AE13: =SUMIFS($I$2:$I$2001,$B$2:$B$2001,">="&$AB13,$B$2:$B$2001,"<"&EDATE($AB13,1),$E$2:$E$2001,AE$1) -> 12325.54 | AF13: =SUMIFS($I$2:$I$2001,$B$2:$B$2001,">="&$AB13,$B$2:$B$2001,"<"&EDATE($AB13,1),$E$2:$E$2001,AF$1) -> 59066.32 | AG13: =SUMIFS($I$2:$I$2001,$B$2:$B$2001,">="&$AB13,$B$2:$B$2001,"<"&EDATE($AB13,1),$E$2:$E$2001,AG$1) -> 68580.8 | AH13: =SUMIFS($I$2:$I$2001,$B$2:$B$2001,">="&$AB13,$B$2:$B$2001,"<"&EDATE($AB13,1),$E$2:$E$2001,AH$1) -> 121741.5 | AI13: =SUMIFS($I$2:$I$2001,$B$2:$B$2001,">="&$AB13,$B$2:$B$2001,"<"&EDATE($AB13,1),$E$2:$E$2001,AI$1) -> 57922.93 | AJ13: =SUMIFS($I$2:$I$2001,$B$2:$B$2001,">="&$AB13,$B$2:$B$2001,"<"&EDATE($AB13,1),$E$2:$E$2001,AJ$1) -> 172732.12 | ... BF13: =SUMIFS($I$2:$I$2001,$B$2:$B$2001,">="&$AB13,$B$2:$B$2001,"<"&EDATE($AB13,1),$E$2:$E$2001,BF$1) -> 47706.74 | BH13: =Products!A13 -> PROD-012 | BI13: =Products!B13 -> Denim Jeans | BJ13: =SUMIFS($I$2:$I$2001,$N$2:$N$2001,"West",$D$2:$D$2001,BH13) -> 121770.6 | BK13: =_xludf.RANK.EQ(BJ13,$BJ$2:$BJ$61,0) -> #NAME? | BL13: 0 | BM13: 0 | BN13: 0.018867925 | BO13: 0 | BP13: 0
A14: =Orders!A14 -> ORD-00013 | B14: =Orders!B14 -> 45507 | C14: =Orders!C14 -> CUST-0280 | D14: =Orders!D14 -> PROD-002 | E14: =Orders!E14 -> R004 | F14: =Orders!F14 -> 3 | G14: =Orders!G14 -> 2600 | H14: =Orders!H14 -> 4.3 | ... K14: =Orders!K14 -> Delhi | L14: =IFERROR(VLOOKUP(D14,Products!$A$2:$F$61,3,FALSE),"") -> Electronics | M14: =IFERROR(VLOOKUP(D14,Products!$A$2:$F$61,4,FALSE),"") -> 1052 | N14: =IFERROR(VLOOKUP(E14,Sales_Reps!$A$2:$E$31,3,FALSE),"") -> North | O14: =IFERROR(VLOOKUP(C14,Customers!$A$2:$F$301,5,FALSE),"") -> SMB | P14: =IFERROR(VLOOKUP(C14,Customers!$A$2:$F$301,3,FALSE),"") -> 27 | Q14: =IFERROR((G14-M14)/G14,0) -> 0.59538462 | R14: =IFERROR(VLOOKUP(C14,Customers!$A$2:$F$301,1,FALSE),"") -> CUST-0280 | S14: =IFERROR(VLOOKUP(D14,Products!$A$2:$F$61,6,FALSE),"") -> TRUE | T14: Q2.5 | U14: 174 | V14: Inactive product helper | W14: =Sales_Reps!A14 -> R013 | X14: =Sales_Reps!B14 -> Sanjay Kapoor | Y14: =SUMIF($E$2:$E$2001,W14,$I$2:$I$2001) -> 811524.38 | Z14: =_xludf.RANK.EQ(Y14,$Y$2:$Y$31,0) -> #NAME? | BH14: =Products!A14 -> PROD-013 | BI14: =Products!B14 -> Formal Shirt | BJ14: =SUMIFS($I$2:$I$2001,$N$2:$N$2001,"West",$D$2:$D$2001,BH14) -> 85543.64 | BK14: =_xludf.RANK.EQ(BJ14,$BJ$2:$BJ$61,0) -> #NAME? | BL14: 0 | BM14: 0 | BN14: 0.023809524 | BO14: 0 | BP14: 0
A15: =Orders!A15 -> ORD-00014 | B15: =Orders!B15 -> 45466 | C15: =Orders!C15 -> CUST-0008 | D15: =Orders!D15 -> PROD-036 | E15: =Orders!E15 -> R025 | F15: =Orders!F15 -> 3 | G15: =Orders!G15 -> 3250 | H15: =Orders!H15 -> 14.1 | ... K15: =Orders!K15 -> Pune | L15: =IFERROR(VLOOKUP(D15,Products!$A$2:$F$61,3,FALSE),"") -> Home | M15: =IFERROR(VLOOKUP(D15,Products!$A$2:$F$61,4,FALSE),"") -> 1556 | N15: =IFERROR(VLOOKUP(E15,Sales_Reps!$A$2:$E$31,3,FALSE),"") -> West | O15: =IFERROR(VLOOKUP(C15,Customers!$A$2:$F$301,5,FALSE),"") -> SMB | P15: =IFERROR(VLOOKUP(C15,Customers!$A$2:$F$301,3,FALSE),"") -> 39 | Q15: =IFERROR((G15-M15)/G15,0) -> 0.52123077 | R15: =IFERROR(VLOOKUP(C15,Customers!$A$2:$F$301,1,FALSE),"") -> CUST-0008 | S15: =IFERROR(VLOOKUP(D15,Products!$A$2:$F$61,6,FALSE),"") -> TRUE | T15: Q2.6 | U15: =COUNTIFS($J$2:$J$2001,"Cancelled",$H$2:$H$2001,">20") -> 58 | V15: COUNTIFS | W15: =Sales_Reps!A15 -> R014 | X15: =Sales_Reps!B15 -> Ritu Menon | Y15: =SUMIF($E$2:$E$2001,W15,$I$2:$I$2001) -> 995713.54 | Z15: =_xludf.RANK.EQ(Y15,$Y$2:$Y$31,0) -> #NAME? | BH15: =Products!A15 -> PROD-014 | BI15: =Products!B15 -> Winter Jacket | BJ15: =SUMIFS($I$2:$I$2001,$N$2:$N$2001,"West",$D$2:$D$2001,BH15) -> 95390.62 | BK15: =_xludf.RANK.EQ(BJ15,$BJ$2:$BJ$61,0) -> #NAME? | BL15: 0 | BM15: 0 | BN15: 0.021276596 | BO15: 0 | BP15: 0
A16: =Orders!A16 -> ORD-00015 | B16: =Orders!B16 -> 45365 | C16: =Orders!C16 -> CUST-0052 | D16: =Orders!D16 -> PROD-060 | E16: =Orders!E16 -> R003 | F16: =Orders!F16 -> 1 | G16: =Orders!G16 -> 190 | H16: =Orders!H16 -> 20.7 | ... K16: =Orders!K16 -> Pune | L16: =IFERROR(VLOOKUP(D16,Products!$A$2:$F$61,3,FALSE),"") -> Sports | M16: =IFERROR(VLOOKUP(D16,Products!$A$2:$F$61,4,FALSE),"") -> 147 | N16: =IFERROR(VLOOKUP(E16,Sales_Reps!$A$2:$E$31,3,FALSE),"") -> North | O16: =IFERROR(VLOOKUP(C16,Customers!$A$2:$F$301,5,FALSE),"") -> Retail | P16: =IFERROR(VLOOKUP(C16,Customers!$A$2:$F$301,3,FALSE),"") -> 38 | Q16: =IFERROR((G16-M16)/G16,0) -> 0.22631579 | R16: =IFERROR(VLOOKUP(C16,Customers!$A$2:$F$301,1,FALSE),"") -> CUST-0052 | S16: =IFERROR(VLOOKUP(D16,Products!$A$2:$F$61,6,FALSE),"") -> TRUE | T16: Q3.1 | U16: =SUMIFS($I$2:$I$2001,$B$2:$B$2001,">="&DATE(2024,7,1),$B$2:$B$2001,"<="&DATE(2024,9,30),$K$2:$K$2001,"Mumbai") -> 1217239 | V16: SUMIFS: date range + city | W16: =Sales_Reps!A16 -> R015 | X16: =Sales_Reps!B16 -> Deepak Shah | Y16: =SUMIF($E$2:$E$2001,W16,$I$2:$I$2001) -> 1091740.2 | Z16: =_xludf.RANK.EQ(Y16,$Y$2:$Y$31,0) -> #NAME? | BH16: =Products!A16 -> PROD-015 | BI16: =Products!B16 -> Sports Shoes | BJ16: =SUMIFS($I$2:$I$2001,$N$2:$N$2001,"West",$D$2:$D$2001,BH16) -> 108190.72 | BK16: =_xludf.RANK.EQ(BJ16,$BJ$2:$BJ$61,0) -> #NAME? | BL16: 0 | BM16: 0 | BN16: 0.018867925 | BO16: 0 | BP16: 0
A17: =Orders!A17 -> ORD-00016 | B17: =Orders!B17 -> 45546 | C17: =Orders!C17 -> CUST-0184 | D17: =Orders!D17 -> PROD-058 | E17: =Orders!E17 -> R014 | F17: =Orders!F17 -> 7 | G17: =Orders!G17 -> 2400 | H17: =Orders!H17 -> 10.2 | ... K17: =Orders!K17 -> Pune | L17: =IFERROR(VLOOKUP(D17,Products!$A$2:$F$61,3,FALSE),"") -> Sports | M17: =IFERROR(VLOOKUP(D17,Products!$A$2:$F$61,4,FALSE),"") -> 974 | N17: =IFERROR(VLOOKUP(E17,Sales_Reps!$A$2:$E$31,3,FALSE),"") -> South | O17: =IFERROR(VLOOKUP(C17,Customers!$A$2:$F$301,5,FALSE),"") -> Retail | P17: =IFERROR(VLOOKUP(C17,Customers!$A$2:$F$301,3,FALSE),"") -> 63 | Q17: =IFERROR((G17-M17)/G17,0) -> 0.59416667 | R17: =IFERROR(VLOOKUP(C17,Customers!$A$2:$F$301,1,FALSE),"") -> CUST-0184 | S17: =IFERROR(VLOOKUP(D17,Products!$A$2:$F$61,6,FALSE),"") -> TRUE | T17: Q3.2 | U17: =COUNTIFS($H$2:$H$2001,">15",$J$2:$J$2001,"Completed") -> 723 | V17: COUNTIFS | W17: =Sales_Reps!A17 -> R016 | X17: =Sales_Reps!B17 -> Anjali Chopra | Y17: =SUMIF($E$2:$E$2001,W17,$I$2:$I$2001) -> 814563.71 | Z17: =_xludf.RANK.EQ(Y17,$Y$2:$Y$31,0) -> #NAME? | BH17: =Products!A17 -> PROD-016 | BI17: =Products!B17 -> Casual Sneakers | BJ17: =SUMIFS($I$2:$I$2001,$N$2:$N$2001,"West",$D$2:$D$2001,BH17) -> 12964.82 | BK17: =_xludf.RANK.EQ(BJ17,$BJ$2:$BJ$61,0) -> #NAME? | BL17: 0 | BM17: 0 | BN17: 0.023809524 | BO17: 0 | BP17: 0
A18: =Orders!A18 -> ORD-00017 | B18: =Orders!B18 -> 45512 | C18: =Orders!C18 -> CUST-0056 | D18: =Orders!D18 -> PROD-028 | E18: =Orders!E18 -> R023 | F18: =Orders!F18 -> 4 | G18: =Orders!G18 -> 3660 | H18: =Orders!H18 -> 2.6 | ... K18: =Orders!K18 -> Bengaluru | L18: =IFERROR(VLOOKUP(D18,Products!$A$2:$F$61,3,FALSE),"") -> Grocery | M18: =IFERROR(VLOOKUP(D18,Products!$A$2:$F$61,4,FALSE),"") -> 2214 | N18: =IFERROR(VLOOKUP(E18,Sales_Reps!$A$2:$E$31,3,FALSE),"") -> East | O18: =IFERROR(VLOOKUP(C18,Customers!$A$2:$F$301,5,FALSE),"") -> SMB | P18: =IFERROR(VLOOKUP(C18,Customers!$A$2:$F$301,3,FALSE),"") -> 46 | Q18: =IFERROR((G18-M18)/G18,0) -> 0.39508197 | R18: =IFERROR(VLOOKUP(C18,Customers!$A$2:$F$301,1,FALSE),"") -> CUST-0056 | S18: =IFERROR(VLOOKUP(D18,Products!$A$2:$F$61,6,FALSE),"") -> FALSE | T18: Q3.3 | U18: =AVERAGEIFS($I$2:$I$2001,$L$2:$L$2001,"Electronics",$O$2:$O$2001,"Corporate") -> 13981.402 | V18: AVERAGEIFS with helpers | W18: =Sales_Reps!A18 -> R017 | X18: =Sales_Reps!B18 -> Naveen Singh | Y18: =SUMIF($E$2:$E$2001,W18,$I$2:$I$2001) -> 780384.41 | Z18: =_xludf.RANK.EQ(Y18,$Y$2:$Y$31,0) -> #NAME? | BH18: =Products!A18 -> PROD-017 | BI18: =Products!B18 -> Silk Saree | BJ18: =SUMIFS($I$2:$I$2001,$N$2:$N$2001,"West",$D$2:$D$2001,BH18) -> 84699.95 | BK18: =_xludf.RANK.EQ(BJ18,$BJ$2:$BJ$61,0) -> #NAME? | BL18: 0 | BM18: 0 | BN18: 0.023809524 | BO18: 0 | BP18: 1
A19: =Orders!A19 -> ORD-00018 | B19: =Orders!B19 -> 45654 | C19: =Orders!C19 -> CUST-0273 | D19: =Orders!D19 -> PROD-047 | E19: =Orders!E19 -> R021 | F19: =Orders!F19 -> 8 | G19: =Orders!G19 -> 3450 | H19: =Orders!H19 -> 18.5 | ... K19: =Orders!K19 -> Hyderabad | L19: =IFERROR(VLOOKUP(D19,Products!$A$2:$F$61,3,FALSE),"") -> Beauty | M19: =IFERROR(VLOOKUP(D19,Products!$A$2:$F$61,4,FALSE),"") -> 2420 | N19: =IFERROR(VLOOKUP(E19,Sales_Reps!$A$2:$E$31,3,FALSE),"") -> East | O19: =IFERROR(VLOOKUP(C19,Customers!$A$2:$F$301,5,FALSE),"") -> Corporate | P19: =IFERROR(VLOOKUP(C19,Customers!$A$2:$F$301,3,FALSE),"") -> 32 | Q19: =IFERROR((G19-M19)/G19,0) -> 0.29855072 | R19: =IFERROR(VLOOKUP(C19,Customers!$A$2:$F$301,1,FALSE),"") -> CUST-0273 | S19: =IFERROR(VLOOKUP(D19,Products!$A$2:$F$61,6,FALSE),"") -> TRUE | T19: Q3.4 | U19: =SUM(LARGE($Y$2:$Y$31,1),LARGE($Y$2:$Y$31,2),LARGE($Y$2:$Y$31,3)) -> 3342678.5 | V19: Top 3 using LARGE | W19: =Sales_Reps!A19 -> R018 | X19: =Sales_Reps!B19 -> Shalini Patel | Y19: =SUMIF($E$2:$E$2001,W19,$I$2:$I$2001) -> 1112289.6 | Z19: =_xludf.RANK.EQ(Y19,$Y$2:$Y$31,0) -> #NAME? | BH19: =Products!A19 -> PROD-018 | BI19: =Products!B19 -> Kurta Set | BJ19: =SUMIFS($I$2:$I$2001,$N$2:$N$2001,"West",$D$2:$D$2001,BH19) -> 100288.76 | BK19: =_xludf.RANK.EQ(BJ19,$BJ$2:$BJ$61,0) -> #NAME? | BL19: 0 | BM19: 0 | BN19: 0.018867925 | BO19: 0 | BP19: 0
A20: =Orders!A20 -> ORD-00019 | B20: =Orders!B20 -> 45626 | C20: =Orders!C20 -> CUST-0182 | D20: =Orders!D20 -> PROD-051 | E20: =Orders!E20 -> R023 | F20: =Orders!F20 -> 5 | G20: =Orders!G20 -> 3450 | H20: =Orders!H20 -> 7.3 | ... K20: =Orders!K20 -> Mumbai | L20: =IFERROR(VLOOKUP(D20,Products!$A$2:$F$61,3,FALSE),"") -> Sports | M20: =IFERROR(VLOOKUP(D20,Products!$A$2:$F$61,4,FALSE),"") -> 2467 | N20: =IFERROR(VLOOKUP(E20,Sales_Reps!$A$2:$E$31,3,FALSE),"") -> East | O20: =IFERROR(VLOOKUP(C20,Customers!$A$2:$F$301,5,FALSE),"") -> Retail | P20: =IFERROR(VLOOKUP(C20,Customers!$A$2:$F$301,3,FALSE),"") -> 54 | Q20: =IFERROR((G20-M20)/G20,0) -> 0.28492754 | R20: =IFERROR(VLOOKUP(C20,Customers!$A$2:$F$301,1,FALSE),"") -> CUST-0182 | S20: =IFERROR(VLOOKUP(D20,Products!$A$2:$F$61,6,FALSE),"") -> TRUE | T20: Q3.5 | U20: =IF(SUMIFS($I$2:$I$2001,$E$2:$E$2001,"R015",$B$2:$B$2001,">="&DATE(2024,11,1),$B$2:$B$2001,"<="&DATE(2024,11,30))/INDEX(Targets!$A$2:$M$31,MATCH("R015",Targets!$A$2:$A$31,0),MATCH("Nov-24",Targets!$A$1:$M$1,0))<0.8,"Below",IF(SUMIFS($I$2:$I$2001,$E$2:$E$2001,"R015",$B$2:$B$2001,">="&DATE(2024,11,1),$B$2:$B$2001,"<="&DATE(2024,11,30))/INDEX(Targets!$A$2:$M$31,MATCH("R015",Targets!$A$2:$A$31,0),MATCH("Nov-24",Targets!$A$1:$M$1,0))<=1.2,"On Track","Exceeds")) -> Below | V20: Nested IF on actual / target | W20: =Sales_Reps!A20 -> R019 | X20: =Sales_Reps!B20 -> Prakash Shah | Y20: =SUMIF($E$2:$E$2001,W20,$I$2:$I$2001) -> 971183.52 | Z20: =_xludf.RANK.EQ(Y20,$Y$2:$Y$31,0) -> #NAME? | BH20: =Products!A20 -> PROD-019 | BI20: =Products!B20 -> Track Pants | BJ20: =SUMIFS($I$2:$I$2001,$N$2:$N$2001,"West",$D$2:$D$2001,BH20) -> 104993.28 | BK20: =_xludf.RANK.EQ(BJ20,$BJ$2:$BJ$61,0) -> #NAME? | BL20: 0 | BM20: 0 | BN20: 0.018867925 | BO20: 0 | BP20: 0
A21: =Orders!A21 -> ORD-00020 | B21: =Orders!B21 -> 45394 | C21: =Orders!C21 -> CUST-0265 | D21: =Orders!D21 -> PROD-040 | E21: =Orders!E21 -> R023 | F21: =Orders!F21 -> 8 | G21: =Orders!G21 -> 1080 | H21: =Orders!H21 -> 2.2 | ... K21: =Orders!K21 -> Chennai | L21: =IFERROR(VLOOKUP(D21,Products!$A$2:$F$61,3,FALSE),"") -> Home | M21: =IFERROR(VLOOKUP(D21,Products!$A$2:$F$61,4,FALSE),"") -> 519 | N21: =IFERROR(VLOOKUP(E21,Sales_Reps!$A$2:$E$31,3,FALSE),"") -> East | O21: =IFERROR(VLOOKUP(C21,Customers!$A$2:$F$301,5,FALSE),"") -> Retail | P21: =IFERROR(VLOOKUP(C21,Customers!$A$2:$F$301,3,FALSE),"") -> 49 | Q21: =IFERROR((G21-M21)/G21,0) -> 0.51944444 | R21: =IFERROR(VLOOKUP(C21,Customers!$A$2:$F$301,1,FALSE),"") -> CUST-0265 | S21: =IFERROR(VLOOKUP(D21,Products!$A$2:$F$61,6,FALSE),"") -> TRUE | T21: Q3.6 | U21: =SUMIFS($I$2:$I$2001,$O$2:$O$2001,"Corporate",$P$2:$P$2001,">=30",$P$2:$P$2001,"<=40") -> 982568.4 | V21: SUMIFS with age band | W21: =Sales_Reps!A21 -> R020 | X21: =Sales_Reps!B21 -> Meera Iyer | Y21: =SUMIF($E$2:$E$2001,W21,$I$2:$I$2001) -> 906107.71 | Z21: =_xludf.RANK.EQ(Y21,$Y$2:$Y$31,0) -> #NAME? | BH21: =Products!A21 -> PROD-020 | BI21: =Products!B21 -> Woolen Sweater | BJ21: =SUMIFS($I$2:$I$2001,$N$2:$N$2001,"West",$D$2:$D$2001,BH21) -> 9173.34 | BK21: =_xludf.RANK.EQ(BJ21,$BJ$2:$BJ$61,0) -> #NAME? | BL21: 0 | BM21: 0 | BN21: 0.019607843 | BO21: 0 | BP21: 0
